Workbook

Sheet BC
A1: Lane编号 | B1: 文库编号 | C1: Qubit浓度（ng/ul） | D1: 数据量（G) | E1: 文库摩尔质量（nM） | F1: 最终取样体积（ul） | G1: 文库类型 | H1: 客户单位 | I1: TE Buffer补充体积（uL） | J1: 孔号 | K1: 板号 | L1: 备注 | M1: 片段 | N1: Qubit浓度（ng/ul） | O1: 文库结构 | P1: 磷酸化* | Q1: 环化*
A2: B1 | B2: LN7-260717-P1-1 | C2: 7.16 | D2: =_xlfn.XLOOKUP(B2,'[5]1'!$D:$D,'[5]1'!$J:$J,0) -> 570 | E2: 50 | F2: =E2/C2*1.5 -> 10.47486 | G2: =_xlfn.XLOOKUP(B2,'[5]1'!$D:$D,'[5]1'!$H:$H,0) -> 宏基因组文库 | H2: =_xlfn.XLOOKUP(B2,'[5]1'!$D:$D,'[5]1'!$L:$L,0) -> 广东美格基因科技有限公司 | I2: =20-F2 -> 9.5251397 | M2: 378 | N2: 7.16
A3: B2 | B3: LN7-260717-P1-2 | C3: 8.44 | D3: =_xlfn.XLOOKUP(B3,'[5]1'!$D:$D,'[5]1'!$J:$J,0) -> 560 | E3: 50 | F3: =E3/C3*1.5 -> 8.8862559 | G3: =_xlfn.XLOOKUP(B3,'[5]1'!$D:$D,'[5]1'!$H:$H,0) -> 宏基因组文库 | H3: =_xlfn.XLOOKUP(B3,'[5]1'!$D:$D,'[5]1'!$L:$L,0) -> 广东美格基因科技有限公司 | I3: =20-F3 -> 11.113744 | M3: 371 | N3: 8.44
A4: B3 | B4: LN7-260717-P1-3 | C4: 8.26 | D4: =_xlfn.XLOOKUP(B4,'[5]1'!$D:$D,'[5]1'!$J:$J,0) -> 570 | E4: 50 | F4: =E4/C4*1.5 -> 9.0799031 | G4: =_xlfn.XLOOKUP(B4,'[5]1'!$D:$D,'[5]1'!$H:$H,0) -> 宏基因组文库 | H4: =_xlfn.XLOOKUP(B4,'[5]1'!$D:$D,'[5]1'!$L:$L,0) -> 广东美格基因科技有限公司 | I4: =20-F4 -> 10.920097 | M4: 418 | N4: 8.26
A5: B4 | B5: LN7-260717-P1-4 | C5: 7.8 | D5: =_xlfn.XLOOKUP(B5,'[5]1'!$D:$D,'[5]1'!$J:$J,0) -> 570 | E5: 50 | F5: =E5/C5*1.5 -> 9.6153846 | G5: =_xlfn.XLOOKUP(B5,'[5]1'!$D:$D,'[5]1'!$H:$H,0) -> 宏基因组文库 | H5: =_xlfn.XLOOKUP(B5,'[5]1'!$D:$D,'[5]1'!$L:$L,0) -> 广东美格基因科技有限公司 | I5: =20-F5 -> 10.384615 | M5: 414 | N5: 7.8
A6: B5 | B6: LN7-260717-P1-5 | C6: 6.7 | D6: =_xlfn.XLOOKUP(B6,'[5]1'!$D:$D,'[5]1'!$J:$J,0) -> 570 | E6: 50 | F6: =E6/C6*1.5 -> 11.19403 | G6: =_xlfn.XLOOKUP(B6,'[5]1'!$D:$D,'[5]1'!$H:$H,0) -> 宏基因组文库 | H6: =_xlfn.XLOOKUP(B6,'[5]1'!$D:$D,'[5]1'!$L:$L,0) -> 广东美格基因科技有限公司 | I6: =20-F6 -> 8.8059701 | M6: 384 | N6: 6.7
A7: B6 | B7: LN7-260717-P1-6 | C7: 6 | D7: =_xlfn.XLOOKUP(B7,'[5]1'!$D:$D,'[5]1'!$J:$J,0) -> 573 | E7: 50 | F7: =E7/C7*1.5 -> 12.5 | G7: =_xlfn.XLOOKUP(B7,'[5]1'!$D:$D,'[5]1'!$H:$H,0) -> 宏基因组文库 | H7: =_xlfn.XLOOKUP(B7,'[5]1'!$D:$D,'[5]1'!$L:$L,0) -> 广东美格基因科技有限公司 | I7: =20-F7 -> 7.5 | M7: 408 | N7: 6
A8: B7 | B8: LN7-260717-P1-7 | C8: 5.94 | D8: =_xlfn.XLOOKUP(B8,'[5]1'!$D:$D,'[5]1'!$J:$J,0) -> 350 | E8: 50 | F8: =E8/C8*1.5 -> 12.626263 | G8: =_xlfn.XLOOKUP(B8,'[5]1'!$D:$D,'[5]1'!$H:$H,0) -> 宏基因组文库 | H8: =_xlfn.XLOOKUP(B8,'[5]1'!$D:$D,'[5]1'!$L:$L,0) -> 广东美格基因科技有限公司 | I8: =20-F8 -> 7.3737374 | M8: 416 | N8: 5.94
A10: C1 | B10: HGC-Lib-26085649 | C10: 54.09 | D10: =_xlfn.XLOOKUP(B10,'[5]2'!$C:$C,'[5]2'!$J:$J,0) -> 0.6 | E10: =D10/$D$14*300 -> 82.568807 | F10: =E10/C10 -> 1.5265078 | G10: =_xlfn.XLOOKUP(B10,'[5]2'!$C:$C,'[5]2'!$H:$H,0) -> 基因组文库 | H10: =_xlfn.XLOOKUP(B10,'[5]2'!$C:$C,'[5]2'!$L:$L,0) -> 武汉百易汇能生物科技有限公司 | K10: =VLOOKUP(B10,'[3]7月份'!$F:$O,10,0) -> 0713百易汇能-D7 | L10: =_xlfn.XLOOKUP(B10,'[5]2'!$C:$C,'[5]2'!$M:$M,0) -> 补测_260717_R21016100250033_ML150022394 | M10: =VLOOKUP(B10,'[3]7月份'!$F:$M,8,0) -> 317 | N10: =VLOOKUP(B10,'[3]7月份'!$F:$L,7,0) -> 54.09 | O10: =VLOOKUP(B10,'[3]7月份'!$F:$V,17,0) -> 华大双barcode文库 | P10: =VLOOKUP(B10,'[3]7月份'!$F:$W,18,0) -> 已磷酸化 | Q10: =VLOOKUP(B10,'[3]7月份'!$F:$X,19,0) -> 未环化
B11: HGC-Lib-26085647 | C11: 57.95 | D11: =_xlfn.XLOOKUP(B11,'[5]2'!$C:$C,'[5]2'!$J:$J,0) -> 0.72 | E11: =D11/$D$14*300 -> 99.082569 | F11: =E11/C11 -> 1.7097941 | G11: =_xlfn.XLOOKUP(B11,'[5]2'!$C:$C,'[5]2'!$H:$H,0) -> 基因组文库 | H11: =_xlfn.XLOOKUP(B11,'[5]2'!$C:$C,'[5]2'!$L:$L,0) -> 武汉百易汇能生物科技有限公司 | K11: =VLOOKUP(B11,'[3]7月份'!$F:$O,10,0) -> 0713百易汇能-B7 | L11: =_xlfn.XLOOKUP(B11,'[5]2'!$C:$C,'[5]2'!$M:$M,0) -> 补测_260717_R21016100250033_ML150022394 | M11: =VLOOKUP(B11,'[3]7月份'!$F:$M,8,0) -> 314 | N11: =VLOOKUP(B11,'[3]7月份'!$F:$L,7,0) -> 57.95 | O11: =VLOOKUP(B11,'[3]7月份'!$F:$V,17,0) -> 华大双barcode文库 | P11: =VLOOKUP(B11,'[3]7月份'!$F:$W,18,0) -> 已磷酸化 | Q11: =VLOOKUP(B11,'[3]7月份'!$F:$X,19,0) -> 未环化
B12: HGC-Lib-26085659 | C12: 55.48 | D12: =_xlfn.XLOOKUP(B12,'[5]2'!$C:$C,'[5]2'!$J:$J,0) -> 0.3 | E12: =D12/$D$14*300 -> 41.284404 | F12: =E12/C12 -> 0.74413128 | G12: =_xlfn.XLOOKUP(B12,'[5]2'!$C:$C,'[5]2'!$H:$H,0) -> 基因组文库 | H12: =_xlfn.XLOOKUP(B12,'[5]2'!$C:$C,'[5]2'!$L:$L,0) -> 武汉百易汇能生物科技有限公司 | K12: =VLOOKUP(B12,'[3]7月份'!$F:$O,10,0) -> 0713百易汇能-F8 | L12: =_xlfn.XLOOKUP(B12,'[5]2'!$C:$C,'[5]2'!$M:$M,0) -> 补测_260717_R21016100250033_ML150022394 | M12: =VLOOKUP(B12,'[3]7月份'!$F:$M,8,0) -> 335 | N12: =VLOOKUP(B12,'[3]7月份'!$F:$L,7,0) -> 55.48 | O12: =VLOOKUP(B12,'[3]7月份'!$F:$V,17,0) -> 华大双barcode文库 | P12: =VLOOKUP(B12,'[3]7月份'!$F:$W,18,0) -> 已磷酸化 | Q12: =VLOOKUP(B12,'[3]7月份'!$F:$X,19,0) -> 未环化
B13: HGC-Lib-26085658 | C13: 51.96 | D13: =_xlfn.XLOOKUP(B13,'[5]2'!$C:$C,'[5]2'!$J:$J,0) -> 0.56 | E13: =D13/$D$14*300 -> 77.06422 | F13: =E13/C13 -> 1.4831451 | G13: =_xlfn.XLOOKUP(B13,'[5]2'!$C:$C,'[5]2'!$H:$H,0) -> 基因组文库 | H13: =_xlfn.XLOOKUP(B13,'[5]2'!$C:$C,'[5]2'!$L:$L,0) -> 武汉百易汇能生物科技有限公司 | K13: =VLOOKUP(B13,'[3]7月份'!$F:$O,10,0) -> 0713百易汇能-E8 | L13: =_xlfn.XLOOKUP(B13,'[5]2'!$C:$C,'[5]2'!$M:$M,0) -> 补测_260717_R21016100250033_ML150022394 | M13: =VLOOKUP(B13,'[3]7月份'!$F:$M,8,0) -> 328 | N13: =VLOOKUP(B13,'[3]7月份'!$F:$L,7,0) -> 51.96 | O13: =VLOOKUP(B13,'[3]7月份'!$F:$V,17,0) -> 华大双barcode文库 | P13: =VLOOKUP(B13,'[3]7月份'!$F:$W,18,0) -> 已磷酸化 | Q13: =VLOOKUP(B13,'[3]7月份'!$F:$X,19,0) -> 未环化
D14: =SUM(D10:D13) -> 2.18 | E14: =SUM(E10:E13) -> 300 | F14: =SUM(F10:F13) -> 5.4635783 | I14: =40-F14 -> 34.536422 | M14: =AVERAGE(M10:M13) -> 323.5
A15: C2 | B15: HGC-Lib-26088722 | C15: 66.89 | D15: =_xlfn.XLOOKUP(B15,'[5]2'!$C:$C,'[5]2'!$J:$J,0) -> 12.34 | E15: =D15/$D$18*300 -> 106.16576 | F15: =E15/C15 -> 1.5871694 | G15: =_xlfn.XLOOKUP(B15,'[5]2'!$C:$C,'[5]2'!$H:$H,0) -> 链特异性文库 | H15: =_xlfn.XLOOKUP(B15,'[5]2'!$C:$C,'[5]2'!$L:$L,0) -> 武汉百易汇能生物科技有限公司 | K15: =VLOOKUP(B15,'[3]7月份'!$F:$O,10,0) -> 0 | L15: =_xlfn.XLOOKUP(B15,'[5]2'!$C:$C,'[5]2'!$M:$M,0) -> 补测_260717_R21016100250033_ML150022394 | M15: =VLOOKUP(B15,'[3]7月份'!$F:$M,8,0) -> 332 | N15: =VLOOKUP(B15,'[3]7月份'!$F:$L,7,0) -> 66.89 | O15: =VLOOKUP(B15,'[3]7月份'!$F:$V,17,0) -> 华大双barcode文库 | P15: =VLOOKUP(B15,'[3]7月份'!$F:$W,18,0) -> 已磷酸化 | Q15: =VLOOKUP(B15,'[3]7月份'!$F:$X,19,0) -> 未环化
B16: HGC-Lib-26088726 | C16: 63.16 | D16: =_xlfn.XLOOKUP(B16,'[5]2'!$C:$C,'[5]2'!$J:$J,0) -> 6.74 | E16: =D16/$D$18*300 -> 57.986808 | F16: =E16/C16 -> 0.91809386 | G16: =_xlfn.XLOOKUP(B16,'[5]2'!$C:$C,'[5]2'!$H:$H,0) -> 链特异性文库 | H16: =_xlfn.XLOOKUP(B16,'[5]2'!$C:$C,'[5]2'!$L:$L,0) -> 武汉百易汇能生物科技有限公司 | K16: =VLOOKUP(B16,'[3]7月份'!$F:$O,10,0) -> 0 | L16: =_xlfn.XLOOKUP(B16,'[5]2'!$C:$C,'[5]2'!$M:$M,0) -> 补测_260717_R21016100250033_ML150022394 | M16: =VLOOKUP(B16,'[3]7月份'!$F:$M,8,0) -> 357 | N16: =VLOOKUP(B16,'[3]7月份'!$F:$L,7,0) -> 63.16 | O16: =VLOOKUP(B16,'[3]7月份'!$F:$V,17,0) -> 华大双barcode文库 | P16: =VLOOKUP(B16,'[3]7月份'!$F:$W,18,0) -> 已磷酸化 | Q16: =VLOOKUP(B16,'[3]7月份'!$F:$X,19,0) -> 未环化
B17: HGC-Lib-26088723 | C17: 38.72 | D17: =_xlfn.XLOOKUP(B17,'[5]2'!$C:$C,'[5]2'!$J:$J,0) -> 15.79 | E17: =D17/$D$18*300 -> 135.84743 | F17: =E17/C17 -> 3.5084564 | G17: =_xlfn.XLOOKUP(B17,'[5]2'!$C:$C,'[5]2'!$H:$H,0) -> 链特异性文库 | H17: =_xlfn.XLOOKUP(B17,'[5]2'!$C:$C,'[5]2'!$L:$L,0) -> 武汉百易汇能生物科技有限公司 | K17: =VLOOKUP(B17,'[3]7月份'!$F:$O,10,0) -> 0 | L17: =_xlfn.XLOOKUP(B17,'[5]2'!$C:$C,'[5]2'!$M:$M,0) -> 补测_260717_R21016100250033_ML150022394 | M17: =VLOOKUP(B17,'[3]7月份'!$F:$M,8,0) -> 317 | N17: =VLOOKUP(B17,'[3]7月份'!$F:$L,7,0) -> 38.72 | O17: =VLOOKUP(B17,'[3]7月份'!$F:$V,17,0) -> 华大双barcode文库 | P17: =VLOOKUP(B17,'[3]7月份'!$F:$W,18,0) -> 已磷酸化 | Q17: =VLOOKUP(B17,'[3]7月份'!$F:$X,19,0) -> 未环化
D18: =SUM(D15:D17) -> 34.87 | E18: =SUM(E15:E17) -> 300 | F18: =SUM(F15:F17) -> 6.0137197 | I18: =40-F18 -> 33.98628 | M18: =AVERAGE(M15:M17) -> 335.33333
A19: C3 | B19: HGC-Lib-26087647 | C19: 20.89 | D19: =_xlfn.XLOOKUP(B19,'[5]2'!$C:$C,'[5]2'!$J:$J,0) -> 11.98 | E19: 150 | F19: =E19/C19 -> 7.1804691 | G19: =_xlfn.XLOOKUP(B19,'[5]2'!$C:$C,'[5]2'!$H:$H,0) -> 转录组文库 | H19: =_xlfn.XLOOKUP(B19,'[5]2'!$C:$C,'[5]2'!$L:$L,0) -> 武汉百易汇能生物科技有限公司 | I19: =40-F19 -> 32.819531 | K19: =VLOOKUP(B19,'[3]7月份'!$F:$O,10,0) -> 0716-1百易汇能-A4 | L19: =_xlfn.XLOOKUP(B19,'[5]2'!$C:$C,'[5]2'!$M:$M,0) -> 补测_260717_R21016100250033_ML150022328 | M19: =VLOOKUP(B19,'[3]7月份'!$F:$M,8,0) -> 334 | N19: =VLOOKUP(B19,'[3]7月份'!$F:$L,7,0) -> 20.89 | O19: =VLOOKUP(B19,'[3]7月份'!$F:$V,17,0) -> 华大双barcode文库 | P19: =VLOOKUP(B19,'[3]7月份'!$F:$W,18,0) -> 已磷酸化 | Q19: =VLOOKUP(B19,'[3]7月份'!$F:$X,19,0) -> 未环化
D20: =SUM(D19:D19) -> 11.98 | M20: =AVERAGE(M19:M19) -> 334
A21: C4 | B21: HGC-Lib-26085620 | C21: 67.97 | D21: =_xlfn.XLOOKUP(B21,'[5]2'!$C:$C,'[5]2'!$J:$J,0) -> 12.17 | E21: 300 | F21: =E21/C21 -> 4.4137119 | G21: =_xlfn.XLOOKUP(B21,'[5]2'!$C:$C,'[5]2'!$H:$H,0) -> 基因组文库 | H21: =_xlfn.XLOOKUP(B21,'[5]2'!$C:$C,'[5]2'!$L:$L,0) -> 武汉百易汇能生物科技有限公司 | I21: =40-F21 -> 35.586288 | K21: =VLOOKUP(B21,'[3]7月份'!$F:$O,10,0) -> 0713百易汇能-G3 | L21: =_xlfn.XLOOKUP(B21,'[5]2'!$C:$C,'[5]2'!$M:$M,0) -> 补测_260717_R21016100250033_ML150022394 | M21: =VLOOKUP(B21,'[3]7月份'!$F:$M,8,0) -> 332 | N21: =VLOOKUP(B21,'[3]7月份'!$F:$L,7,0) -> 67.97 | O21: =VLOOKUP(B21,'[3]7月份'!$F:$V,17,0) -> 华大双barcode文库 | P21: =VLOOKUP(B21,'[3]7月份'!$F:$W,18,0) -> 已磷酸化 | Q21: =VLOOKUP(B21,'[3]7月份'!$F:$X,19,0) -> 未环化
D22: =SUM(D21:D21) -> 12.17 | M22: =AVERAGE(M21:M21) -> 332
A23: C5 | B23: HGC-Lib-26085375 | C23: 19.7 | D23: =_xlfn.XLOOKUP(B23,'[5]2'!$C:$C,'[5]2'!$J:$J,0) -> 4.25 | E23: 150 | F23: =E23/C23 -> 7.6142132 | G23: =_xlfn.XLOOKUP(B23,'[5]2'!$C:$C,'[5]2'!$H:$H,0) -> 华大-C4-转录组 | H23: =_xlfn.XLOOKUP(B23,'[5]2'!$C:$C,'[5]2'!$L:$L,0) -> 广州基迪奥科技服务有限公司 | I23: =40-F23 -> 32.385787 | L23: =_xlfn.XLOOKUP(B23,'[5]2'!$C:$C,'[5]2'!$M:$M,0) -> 补测_260717_R21016100250033_ML150022394 | M23: =VLOOKUP(B23,'[3]7月份'!$F:$M,8,0) -> 0 | N23: =VLOOKUP(B23,'[3]7月份'!$F:$L,7,0) -> 19.7 | O23: =VLOOKUP(B23,'[3]7月份'!$F:$V,17,0) -> Illumina Truseq文库 | P23: =VLOOKUP(B23,'[3]7月份'!$F:$W,18,0) -> 未磷酸化 | Q23: =VLOOKUP(B23,'[3]7月份'!$F:$X,19,0) -> 未环化
D24: =SUM(D23:D23) -> 4.25 | M24: =AVERAGE(M23:M23) -> 0
A25: C6 | B25: HGC-Lib-26084771 | C25: 18.14 | D25: =_xlfn.XLOOKUP(B25,'[5]2'!$C:$C,'[5]2'!$J:$J,0) -> 0.09 | E25: =D25/$D$31*200 -> 25 | F25: =E25/C25 -> 1.3781698 | G25: =_xlfn.XLOOKUP(B25,'[5]2'!$C:$C,'[5]2'!$H:$H,0) -> 华大-C4-oligo | H25: =_xlfn.XLOOKUP(B25,'[5]2'!$C:$C,'[5]2'!$L:$L,0) -> 广州奥智生物科技有限公司 | L25: =_xlfn.XLOOKUP(B25,'[5]2'!$C:$C,'[5]2'!$M:$M,0) -> 补测_260717_R21016100250033_ML150022394 | M25: =VLOOKUP(B25,'[3]7月份'!$F:$M,8,0) -> 0 | N25: =VLOOKUP(B25,'[3]7月份'!$F:$L,7,0) -> 18.14 | O25: =VLOOKUP(B25,'[3]7月份'!$F:$V,17,0) -> 华大单barcode文库 | P25: =VLOOKUP(B25,'[3]7月份'!$F:$W,18,0) -> 已磷酸化 | Q25: =VLOOKUP(B25,'[3]7月份'!$F:$X,19,0) -> 未环化
B26: HGC-Lib-26084765 | C26: 16.45 | D26: =_xlfn.XLOOKUP(B26,'[5]2'!$C:$C,'[5]2'!$J:$J,0) -> 0.13 | E26: =D26/$D$31*200 -> 36.111111 | F26: =E26/C26 -> 2.1952043 | G26: =_xlfn.XLOOKUP(B26,'[5]2'!$C:$C,'[5]2'!$H:$H,0) -> 华大-C4-oligo | H26: =_xlfn.XLOOKUP(B26,'[5]2'!$C:$C,'[5]2'!$L:$L,0) -> 广州奥智生物科技有限公司 | L26: =_xlfn.XLOOKUP(B26,'[5]2'!$C:$C,'[5]2'!$M:$M,0) -> 补测_260717_R21016100250033_ML150022394 | M26: =VLOOKUP(B26,'[3]7月份'!$F:$M,8,0) -> 0 | N26: =VLOOKUP(B26,'[3]7月份'!$F:$L,7,0) -> 16.45 | O26: =VLOOKUP(B26,'[3]7月份'!$F:$V,17,0) -> 华大单barcode文库 | P26: =VLOOKUP(B26,'[3]7月份'!$F:$W,18,0) -> 已磷酸化 | Q26: =VLOOKUP(B26,'[3]7月份'!$F:$X,19,0) -> 未环化
B27: HGC-Lib-26084763 | C27: 13.86 | D27: =_xlfn.XLOOKUP(B27,'[5]2'!$C:$C,'[5]2'!$J:$J,0) -> 0.23 | E27: =D27/$D$31*200 -> 63.888889 | F27: =E27/C27 -> 4.6095879 | G27: =_xlfn.XLOOKUP(B27,'[5]2'!$C:$C,'[5]2'!$H:$H,0) -> 华大-C4-oligo | H27: =_xlfn.XLOOKUP(B27,'[5]2'!$C:$C,'[5]2'!$L:$L,0) -> 广州奥智生物科技有限公司 | L27: =_xlfn.XLOOKUP(B27,'[5]2'!$C:$C,'[5]2'!$M:$M,0) -> 补测_260717_R21016100250033_ML150022394 | M27: =VLOOKUP(B27,'[3]7月份'!$F:$M,8,0) -> 0 | N27: =VLOOKUP(B27,'[3]7月份'!$F:$L,7,0) -> 13.86 | O27: =VLOOKUP(B27,'[3]7月份'!$F:$V,17,0) -> 华大单barcode文库 | P27: =VLOOKUP(B27,'[3]7月份'!$F:$W,18,0) -> 已磷酸化 | Q27: =VLOOKUP(B27,'[3]7月份'!$F:$X,19,0) -> 未环化
B28: HGC-Lib-26084739 | C28: 13.78 | D28: =_xlfn.XLOOKUP(B28,'[5]2'!$C:$C,'[5]2'!$J:$J,0) -> 0.07 | E28: =D28/$D$31*200 -> 19.444444 | F28: =E28/C28 -> 1.4110627 | G28: =_xlfn.XLOOKUP(B28,'[5]2'!$C:$C,'[5]2'!$H:$H,0) -> 华大-C4-oligo | H28: =_xlfn.XLOOKUP(B28,'[5]2'!$C:$C,'[5]2'!$L:$L,0) -> 广州奥智生物科技有限公司 | L28: =_xlfn.XLOOKUP(B28,'[5]2'!$C:$C,'[5]2'!$M:$M,0) -> 补测_260717_R21016100250033_ML150022394 | M28: =VLOOKUP(B28,'[3]7月份'!$F:$M,8,0) -> 0 | N28: =VLOOKUP(B28,'[3]7月份'!$F:$L,7,0) -> 13.78 | O28: =VLOOKUP(B28,'[3]7月份'!$F:$V,17,0) -> 华大单barcode文库 | P28: =VLOOKUP(B28,'[3]7月份'!$F:$W,18,0) -> 已磷酸化 | Q28: =VLOOKUP(B28,'[3]7月份'!$F:$X,19,0) -> 未环化
B29: HGC-Lib-26083226 | C29: 15.02 | D29: =_xlfn.XLOOKUP(B29,'[5]2'!$C:$C,'[5]2'!$J:$J,0) -> 0.01 | E29: =D29/$D$31*200 -> 2.7777778 | F29: 0.25 | G29: =_xlfn.XLOOKUP(B29,'[5]2'!$C:$C,'[5]2'!$H:$H,0) -> 华大-C4-oligo | H29: =_xlfn.XLOOKUP(B29,'[5]2'!$C:$C,'[5]2'!$L:$L,0) -> 广州奥智生物科技有限公司 | L29: =_xlfn.XLOOKUP(B29,'[5]2'!$C:$C,'[5]2'!$M:$M,0) -> 补测_260717_R21016100250033_ML150022394 | M29: =VLOOKUP(B29,'[3]7月份'!$F:$M,8,0) -> 0 | N29: =VLOOKUP(B29,'[3]7月份'!$F:$L,7,0) -> 15.02 | O29: =VLOOKUP(B29,'[3]7月份'!$F:$V,17,0) -> 华大单barcode文库 | P29: =VLOOKUP(B29,'[3]7月份'!$F:$W,18,0) -> 已磷酸化 | Q29: =VLOOKUP(B29,'[3]7月份'!$F:$X,19,0) -> 未环化
B30: HGC-Lib-26083218 | C30: 17.44 | D30: =_xlfn.XLOOKUP(B30,'[5]2'!$C:$C,'[5]2'!$J:$J,0) -> 0.19 | E30: =D30/$D$31*200 -> 52.777778 | F30: =E30/C30 -> 3.0262487 | G30: =_xlfn.XLOOKUP(B30,'[5]2'!$C:$C,'[5]2'!$H:$H,0) -> 华大-C4-oligo | H30: =_xlfn.XLOOKUP(B30,'[5]2'!$C:$C,'[5]2'!$L:$L,0) -> 广州奥智生物科技有限公司 | L30: =_xlfn.XLOOKUP(B30,'[5]2'!$C:$C,'[5]2'!$M:$M,0) -> 补测_260717_R21016100250033_ML150022394 | M30: =VLOOKUP(B30,'[3]7月份'!$F:$M,8,0) -> 0 | N30: =VLOOKUP(B30,'[3]7月份'!$F:$L,7,0) -> 17.44 | O30: =VLOOKUP(B30,'[3]7月份'!$F:$V,17,0) -> 华大单barcode文库 | P30: =VLOOKUP(B30,'[3]7月份'!$F:$W,18,0) -> 已磷酸化 | Q30: =VLOOKUP(B30,'[3]7月份'!$F:$X,19,0) -> 未环化
D31: =SUM(D25:D30) -> 0.72 | E31: =SUM(E25:E30) -> 200 | F31: =SUM(F25:F30) -> 12.870274 | I31: =40-F31 -> 27.129726 | M31: =AVERAGE(M25:M30) -> 0
A32: C7(10NG) | B32: HGC-Lib-26086170 | C32: 2.22 | D32: =_xlfn.XLOOKUP(B32,'[5]2'!$C:$C,'[5]2'!$J:$J,0) -> 1 | E32: =D32/$D$36*10 -> 2.5 | F32: =E32/C32 -> 1.1261261 | G32: =_xlfn.XLOOKUP(B32,'[5]2'!$C:$C,'[5]2'!$H:$H,0) -> 真核转录组文库 | H32: =_xlfn.XLOOKUP(B32,'[5]2'!$C:$C,'[5]2'!$L:$L,0) -> 广东美格基因科技有限公司 | K32: =VLOOKUP(B32,'[3]7月份'!$F:$O,10,0) -> 单管 | L32: =_xlfn.XLOOKUP(B32,'[5]2'!$C:$C,'[5]2'!$M:$M,0) -> 补测_260717_R21016100250033_ML150022328 | M32: =VLOOKUP(B32,'[3]7月份'!$F:$M,8,0) -> 0 | N32: =VLOOKUP(B32,'[3]7月份'!$F:$L,7,0) -> 2.22 | O32: =VLOOKUP(B32,'[3]7月份'!$F:$V,17,0) -> 0 | P32: =VLOOKUP(B32,'[3]7月份'!$F:$W,18,0) -> 0 | Q32: =VLOOKUP(B32,'[3]7月份'!$F:$X,19,0) -> 0
B33: HGC-Lib-26086171 | C33: 1 | D33: =_xlfn.XLOOKUP(B33,'[5]2'!$C:$C,'[5]2'!$J:$J,0) -> 1 | E33: =D33/$D$36*10 -> 2.5 | F33: =E33/C33 -> 2.5 | G33: =_xlfn.XLOOKUP(B33,'[5]2'!$C:$C,'[5]2'!$H:$H,0) -> 真核转录组文库 | H33: =_xlfn.XLOOKUP(B33,'[5]2'!$C:$C,'[5]2'!$L:$L,0) -> 广东美格基因科技有限公司 | K33: =VLOOKUP(B33,'[3]7月份'!$F:$O,10,0) -> 单管 | L33: =_xlfn.XLOOKUP(B33,'[5]2'!$C:$C,'[5]2'!$M:$M,0) -> 补测_260717_R21016100250033_ML150022328 | M33: =VLOOKUP(B33,'[3]7月份'!$F:$M,8,0) -> 0 | N33: =VLOOKUP(B33,'[3]7月份'!$F:$L,7,0) -> 1 | O33: =VLOOKUP(B33,'[3]7月份'!$F:$V,17,0) -> 0 | P33: =VLOOKUP(B33,'[3]7月份'!$F:$W,18,0) -> 0 | Q33: =VLOOKUP(B33,'[3]7月份'!$F:$X,19,0) -> 0
B34: HGC-Lib-26086173 | C34: 1.25 | D34: =_xlfn.XLOOKUP(B34,'[5]2'!$C:$C,'[5]2'!$J:$J,0) -> 1 | E34: =D34/$D$36*10 -> 2.5 | F34: =E34/C34 -> 2 | G34: =_xlfn.XLOOKUP(B34,'[5]2'!$C:$C,'[5]2'!$H:$H,0) -> 真核转录组文库 | H34: =_xlfn.XLOOKUP(B34,'[5]2'!$C:$C,'[5]2'!$L:$L,0) -> 广东美格基因科技有限公司 | K34: =VLOOKUP(B34,'[3]7月份'!$F:$O,10,0) -> 单管 | L34: =_xlfn.XLOOKUP(B34,'[5]2'!$C:$C,'[5]2'!$M:$M,0) -> 补测_260717_R21016100250033_ML150022328 | M34: =VLOOKUP(B34,'[3]7月份'!$F:$M,8,0) -> 0 | N34: =VLOOKUP(B34,'[3]7月份'!$F:$L,7,0) -> 1.25 | O34: =VLOOKUP(B34,'[3]7月份'!$F:$V,17,0) -> 0 | P34: =VLOOKUP(B34,'[3]7月份'!$F:$W,18,0) -> 0 | Q34: =VLOOKUP(B34,'[3]7月份'!$F:$X,19,0) -> 0
B35: HGC-Lib-26086174 | C35: 2.58 | D35: =_xlfn.XLOOKUP(B35,'[5]2'!$C:$C,'[5]2'!$J:$J,0) -> 1 | E35: =D35/$D$36*10 -> 2.5 | F35: =E35/C35 -> 0.96899225 | G35: =_xlfn.XLOOKUP(B35,'[5]2'!$C:$C,'[5]2'!$H:$H,0) -> 真核转录组文库 | H35: =_xlfn.XLOOKUP(B35,'[5]2'!$C:$C,'[5]2'!$L:$L,0) -> 广东美格基因科技有限公司 | K35: =VLOOKUP(B35,'[3]7月份'!$F:$O,10,0) -> 单管 | L35: =_xlfn.XLOOKUP(B35,'[5]2'!$C:$C,'[5]2'!$M:$M,0) -> 补测_260717_R21016100250033_ML150022328 | M35: =VLOOKUP(B35,'[3]7月份'!$F:$M,8,0) -> 0 | N35: =VLOOKUP(B35,'[3]7月份'!$F:$L,7,0) -> 2.58 | O35: =VLOOKUP(B35,'[3]7月份'!$F:$V,17,0) -> 0 | P35: =VLOOKUP(B35,'[3]7月份'!$F:$W,18,0) -> 0 | Q35: =VLOOKUP(B35,'[3]7月份'!$F:$X,19,0) -> 0
D36: =SUM(D32:D35) -> 4 | E36: =SUM(E32:E35) -> 10 | F36: =SUM(F32:F35) -> 6.5951184 | I36: =20-F36 -> 13.404882
A37: C8(10NG) | B37: HGC-Lib-26089838 | C37: 2.94 | D37: =_xlfn.XLOOKUP(B37,'[5]2'!$C:$C,'[5]2'!$J:$J,0) -> 150 | E37: =D37/$D$39*10 -> 3.75 | F37: =E37/C37 -> 1.2755102 | G37: =_xlfn.XLOOKUP(B37,'[5]2'!$C:$C,'[5]2'!$H:$H,0) -> 新格元3端单细胞转录组 | H37: =_xlfn.XLOOKUP(B37,'[5]2'!$C:$C,'[5]2'!$L:$L,0) -> 深圳达普生物科技有限公司 | L37: =_xlfn.XLOOKUP(B37,'[5]2'!$C:$C,'[5]2'!$M:$M,0) -> 0 | M37: =VLOOKUP(B37,'[3]7月份'!$F:$M,8,0) -> / | N37: =VLOOKUP(B37,'[3]7月份'!$F:$L,7,0) -> 2.94 | O37: =VLOOKUP(B37,'[3]7月份'!$F:$V,17,0) -> Illumina Truseq文库 | P37: =VLOOKUP(B37,'[3]7月份'!$F:$W,18,0) -> 未磷酸化 | Q37: =VLOOKUP(B37,'[3]7月份'!$F:$X,19,0) -> 未环化
B38: HGC-Lib-26089837 | C38: 4.38 | D38: =_xlfn.XLOOKUP(B38,'[5]2'!$C:$C,'[5]2'!$J:$J,0) -> 250 | E38: =D38/$D$39*10 -> 6.25 | F38: =E38/C38 -> 1.4269406 | G38: =_xlfn.XLOOKUP(B38,'[5]2'!$C:$C,'[5]2'!$H:$H,0) -> 新格元3端单细胞转录组 | H38: =_xlfn.XLOOKUP(B38,'[5]2'!$C:$C,'[5]2'!$L:$L,0) -> 深圳达普生物科技有限公司 | L38: =_xlfn.XLOOKUP(B38,'[5]2'!$C:$C,'[5]2'!$M:$M,0) -> 0 | M38: =VLOOKUP(B38,'[3]7月份'!$F:$M,8,0) -> / | N38: =VLOOKUP(B38,'[3]7月份'!$F:$L,7,0) -> 4.38 | O38: =VLOOKUP(B38,'[3]7月份'!$F:$V,17,0) -> Illumina Truseq文库 | P38: =VLOOKUP(B38,'[3]7月份'!$F:$W,18,0) -> 未磷酸化 | Q38: =VLOOKUP(B38,'[3]7月份'!$F:$X,19,0) -> 未环化
D39: =SUM(D37:D38) -> 400 | E39: =SUM(E37:E38) -> 10 | F39: =SUM(F37:F38) -> 2.7024508 | I39: =20-F39 -> 17.297549
A40: C9 | B40: 20260718R-P3-108 | C40: 45.08 | D40: 108 | E40: 50 | F40: =E40/C40 -> 1.1091393 | G40: mRNA-T7 | H40: 武汉格信生物科技有限公司 | I40: =20-F40 -> 18.890861 | L40: =_xlfn.XLOOKUP(B40,'[5]2'!$C:$C,'[5]2'!$M:$M,0) -> 0 | M40: =VLOOKUP(B40,[4]自建库出库报告总表!$D:$N,11,0) -> 490 | N40: =VLOOKUP(B40,[4]自建库出库报告总表!$D:$K,8,0) -> 45.08 | O40: =VLOOKUP(B40,'[3]7月份'!$F:$V,17,0) -> #N/A | P40: =VLOOKUP(B40,'[3]7月份'!$F:$W,18,0) -> #N/A | Q40: =VLOOKUP(B40,'[3]7月份'!$F:$X,19,0) -> #N/A
D41: =SUM(D40:D40) -> 108
...

Sheet 文库环化
A1: 文库编号 | B1: 浓度 | C1: 主峰片段 | D1: 1pmol产物对应质量（ng） | E1: 数据量（G) | F1: 文库摩尔质量（nM） | G1: 最终取样体积（ul） | H1: 文库类型 | I1: 客户单位 | J1: TE Buffer补充体积（uL） | K1: 环化个数 | L1: 环化浓度 | M1: 环化效率
A2: B1 | C2: 500 | D2: =C2*0.66*1 -> 330 | E2: 570 | F2: =D2 -> 330 | G2: =F2/B2 -> #DIV/0! | H2: =_xlfn.XLOOKUP(A2,BC!A:A,BC!G:G,0) -> 宏基因组文库 | I2: =_xlfn.XLOOKUP(A2,BC!A:A,BC!H:H,0) -> 广东美格基因科技有限公司 | J2: =40-G2 -> #DIV/0! | M2: =22*L2/F2 -> 0
A3: B2 | C3: 500 | D3: =C3*0.66*1 -> 330 | E3: 560 | F3: =D3 -> 330 | G3: =F3/B3 -> #DIV/0! | H3: =_xlfn.XLOOKUP(A3,BC!A:A,BC!G:G,0) -> 宏基因组文库 | I3: =_xlfn.XLOOKUP(A3,BC!A:A,BC!H:H,0) -> 广东美格基因科技有限公司 | J3: =40-G3 -> #DIV/0! | M3: =22*L3/F3 -> 0
A4: B3 | C4: 500 | D4: =C4*0.66*1 -> 330 | E4: 570 | F4: =D4 -> 330 | G4: =F4/B4 -> #DIV/0! | H4: =_xlfn.XLOOKUP(A4,BC!A:A,BC!G:G,0) -> 宏基因组文库 | I4: =_xlfn.XLOOKUP(A4,BC!A:A,BC!H:H,0) -> 广东美格基因科技有限公司 | J4: =40-G4 -> #DIV/0! | M4: =22*L4/F4 -> 0
A5: B4 | C5: 500 | D5: =C5*0.66*1 -> 330 | E5: 570 | F5: =D5 -> 330 | G5: =F5/B5 -> #DIV/0! | H5: =_xlfn.XLOOKUP(A5,BC!A:A,BC!G:G,0) -> 宏基因组文库 | I5: =_xlfn.XLOOKUP(A5,BC!A:A,BC!H:H,0) -> 广东美格基因科技有限公司 | J5: =40-G5 -> #DIV/0! | M5: =22*L5/F5 -> 0
A6: B5 | C6: 500 | D6: =C6*0.66*1 -> 330 | E6: 570 | F6: =D6 -> 330 | G6: =F6/B6 -> #DIV/0! | H6: =_xlfn.XLOOKUP(A6,BC!A:A,BC!G:G,0) -> 宏基因组文库 | I6: =_xlfn.XLOOKUP(A6,BC!A:A,BC!H:H,0) -> 广东美格基因科技有限公司 | J6: =40-G6 -> #DIV/0! | M6: =22*L6/F6 -> 0
A7: B6 | C7: 500 | D7: =C7*0.66*1 -> 330 | E7: 573 | F7: =D7 -> 330 | G7: =F7/B7 -> #DIV/0! | H7: =_xlfn.XLOOKUP(A7,BC!A:A,BC!G:G,0) -> 宏基因组文库 | I7: =_xlfn.XLOOKUP(A7,BC!A:A,BC!H:H,0) -> 广东美格基因科技有限公司 | J7: =40-G7 -> #DIV/0! | M7: =22*L7/F7 -> 0
A8: B7 | C8: 500 | D8: =C8*0.66*1 -> 330 | E8: 350 | F8: =D8 -> 330 | G8: =F8/B8 -> #DIV/0! | H8: =_xlfn.XLOOKUP(A8,BC!A:A,BC!G:G,0) -> 宏基因组文库 | I8: =_xlfn.XLOOKUP(A8,BC!A:A,BC!H:H,0) -> 广东美格基因科技有限公司 | J8: =40-G8 -> #DIV/0! | M8: =22*L8/F8 -> 0
E9: =SUM(E2:E8) -> 3763
A11: C1 | B11: / | C11: 323.5 | D11: =C11*0.66*1 -> 213.51 | E11: 2.18 | F11: =D11 -> 213.51 | G11: =F11/B11 -> #VALUE! | H11: =_xlfn.XLOOKUP(A11,BC!A:A,BC!G:G,0) -> 基因组文库 | I11: =_xlfn.XLOOKUP(A11,BC!A:A,BC!H:H,0) -> 武汉百易汇能生物科技有限公司 | J11: =40-G11 -> #VALUE! | M11: =22*L11/F11 -> 0
A12: C2 | B12: / | C12: 335.33333 | D12: =C12*0.66*1 -> 221.32 | E12: 34.87 | F12: =D12 -> 221.32 | G12: =F12/B12 -> #VALUE! | H12: =_xlfn.XLOOKUP(A12,BC!A:A,BC!G:G,0) -> 链特异性文库 | I12: =_xlfn.XLOOKUP(A12,BC!A:A,BC!H:H,0) -> 武汉百易汇能生物科技有限公司 | J12: =40-G12 -> #VALUE! | M12: =22*L12/F12 -> 0
A13: C3 | B13: / | C13: 334 | D13: =C13*0.66*1 -> 220.44 | E13: 11.98 | F13: =D13 -> 220.44 | G13: =F13/B13 -> #VALUE! | H13: =_xlfn.XLOOKUP(A13,BC!A:A,BC!G:G,0) -> 转录组文库 | I13: =_xlfn.XLOOKUP(A13,BC!A:A,BC!H:H,0) -> 武汉百易汇能生物科技有限公司 | J13: =40-G13 -> #VALUE! | M13: =22*L13/F13 -> 0
A14: C4 | B14: / | C14: 332 | D14: =C14*0.66*1 -> 219.12 | E14: 12.17 | F14: =D14 -> 219.12 | G14: =F14/B14 -> #VALUE! | H14: =_xlfn.XLOOKUP(A14,BC!A:A,BC!G:G,0) -> 基因组文库 | I14: =_xlfn.XLOOKUP(A14,BC!A:A,BC!H:H,0) -> 武汉百易汇能生物科技有限公司 | J14: =40-G14 -> #VALUE! | M14: =22*L14/F14 -> 0
A15: C5 | B15: / | C15: 450 | D15: =C15*0.66*1 -> 297 | E15: 4.25 | F15: =D15 -> 297 | G15: =F15/B15 -> #VALUE! | H15: =_xlfn.XLOOKUP(A15,BC!A:A,BC!G:G,0) -> 华大-C4-转录组 | I15: =_xlfn.XLOOKUP(A15,BC!A:A,BC!H:H,0) -> 广州基迪奥科技服务有限公司 | J15: =40-G15 -> #VALUE! | M15: =22*L15/F15 -> 0
A16: C6 | B16: / | C16: 200 | D16: =C16*0.66*1 -> 132 | E16: 0.72 | F16: =D16 -> 132 | G16: =F16/B16 -> #VALUE! | H16: =_xlfn.XLOOKUP(A16,BC!A:A,BC!G:G,0) -> 华大-C4-oligo | I16: =_xlfn.XLOOKUP(A16,BC!A:A,BC!H:H,0) -> 广州奥智生物科技有限公司 | J16: =40-G16 -> #VALUE! | M16: =22*L16/F16 -> 0
A17: C7(10NG) | C17: 500 | D17: =C17*0.66*1 -> 330 | E17: 4 | F17: =D17/3 -> 110 | G17: =F17/B17 -> #DIV/0! | H17: =_xlfn.XLOOKUP(A17,BC!A:A,BC!G:G,0) -> 真核转录组文库 | I17: =_xlfn.XLOOKUP(A17,BC!A:A,BC!H:H,0) -> 广东美格基因科技有限公司 | J17: =40-G17 -> #DIV/0! | M17: =22*L17/F17 -> 0
A18: C8(10NG) | C18: 500 | D18: =C18*0.66*1 -> 330 | E18: 400 | F18: =D18 -> 330 | G18: =F18/B18 -> #DIV/0! | H18: =_xlfn.XLOOKUP(A18,BC!A:A,BC!G:G,0) -> 新格元3端单细胞转录组 | I18: =_xlfn.XLOOKUP(A18,BC!A:A,BC!H:H,0) -> 深圳达普生物科技有限公司 | J18: =40-G18 -> #DIV/0! | M18: =22*L18/F18 -> 0
A19: C9 | C19: 500 | D19: =C19*0.66*1 -> 330 | E19: 108 | F19: =D19 -> 330 | G19: =F19/B19 -> #DIV/0! | H19: =_xlfn.XLOOKUP(A19,BC!A:A,BC!G:G,0) -> mRNA-T7 | I19: =_xlfn.XLOOKUP(A19,BC!A:A,BC!H:H,0) -> 武汉格信生物科技有限公司 | J19: =40-G19 -> #DIV/0! | M19: =22*L19/F19 -> 0
A20: C10 | C20: 550 | D20: =C20*0.66*1.3 -> 471.9 | E20: 780 | F20: =D20 -> 471.9 | G20: =F20/B20 -> #DIV/0! | H20: =_xlfn.XLOOKUP(A20,BC!A:A,BC!G:G,0) -> singleron-3'转录组文库 | I20: =_xlfn.XLOOKUP(A20,BC!A:A,BC!H:H,0) -> 南京通元医学检验实验室有限公司 | J20: =40-G20 -> #DIV/0! | M20: =22*L20/F20 -> 0
A21: C11 | C21: 550 | D21: =C21*0.66*1 -> 363 | E21: 24 | F21: =D21 -> 363 | G21: =F21/B21 -> #DIV/0! | H21: =_xlfn.XLOOKUP(A21,BC!A:A,BC!G:G,0) -> singleron-单细胞TCR文库 | I21: =_xlfn.XLOOKUP(A21,BC!A:A,BC!H:H,0) -> 南京通元医学检验实验室有限公司 | J21: =40-G21 -> #DIV/0! | M21: =22*L21/F21 -> 0
A22: C12 | C22: 550 | D22: =C22*0.66*1.2 -> 435.6 | E22: 600 | F22: =D22 -> 435.6 | G22: =F22/B22 -> #DIV/0! | H22: =_xlfn.XLOOKUP(A22,BC!A:A,BC!G:G,0) -> BD-单细胞 | I22: =_xlfn.XLOOKUP(A22,BC!A:A,BC!H:H,0) -> 江西烈冰生物科技有限公司 | J22: =40-G22 -> #DIV/0! | M22: =22*L22/F22 -> 0
A23: C13 | C23: 500 | D23: =C23*0.66*1.3 -> 429 | E23: 900 | F23: =D23 -> 429 | G23: =F23/B23 -> #DIV/0! | H23: =_xlfn.XLOOKUP(A23,BC!A:A,BC!G:G,0) -> 新格元3端单细胞转录组 | I23: =_xlfn.XLOOKUP(A23,BC!A:A,BC!H:H,0) -> 深圳达普生物科技有限公司 | J23: =40-G23 -> #DIV/0! | M23: =22*L23/F23 -> 0
A24: C14 | C24: 500 | D24: =C24*0.66*1 -> 330 | E24: 450 | F24: =D24 -> 330 | G24: =F24/B24 -> #DIV/0! | H24: =_xlfn.XLOOKUP(A24,BC!A:A,BC!G:G,0) -> 新格元3端单细胞转录组 | I24: =_xlfn.XLOOKUP(A24,BC!A:A,BC!H:H,0) -> 深圳达普生物科技有限公司 | J24: =40-G24 -> #DIV/0! | M24: =22*L24/F24 -> 0
A25: C15 | C25: 500 | D25: =C25*0.66*1 -> 330 | E25: 10 | F25: =D25 -> 330 | G25: =F25/B25 -> #DIV/0! | H25: =_xlfn.XLOOKUP(A25,BC!A:A,BC!G:G,0) -> 宏基因组文库 | I25: =_xlfn.XLOOKUP(A25,BC!A:A,BC!H:H,0) -> 广东美格基因科技有限公司 | J25: =40-G25 -> #DIV/0! | M25: =22*L25/F25 -> 0
A26: C16 | C26: 500 | D26: =C26*0.66*1 -> 330 | E26: 25 | F26: =D26 -> 330 | G26: =F26/B26 -> #DIV/0! | H26: =_xlfn.XLOOKUP(A26,BC!A:A,BC!G:G,0) -> 宏基因组文库 | I26: =_xlfn.XLOOKUP(A26,BC!A:A,BC!H:H,0) -> 广东美格基因科技有限公司 | J26: =40-G26 -> #DIV/0! | M26: =22*L26/F26 -> 0
A27: C17 | C27: 500 | D27: =C27*0.66*1 -> 330 | E27: 19 | F27: =D27 -> 330 | G27: =F27/B27 -> #DIV/0! | H27: =_xlfn.XLOOKUP(A27,BC!A:A,BC!G:G,0) -> 宏基因组文库 | I27: =_xlfn.XLOOKUP(A27,BC!A:A,BC!H:H,0) -> 广东美格基因科技有限公司 | J27: =40-G27 -> #DIV/0! | M27: =22*L27/F27 -> 0
A28: C18 | C28: 500 | D28: =C28*0.66*1 -> 330 | E28: 0.08 | F28: =D28/3 -> 110 | G28: =F28/B28 -> #DIV/0! | H28: =_xlfn.XLOOKUP(A28,BC!A:A,BC!G:G,0) -> 有参转录组（RNA-seq） | I28: =_xlfn.XLOOKUP(A28,BC!A:A,BC!H:H,0) -> 广州奥智生物科技有限公司 | J28: =40-G28 -> #DIV/0! | M28: =22*L28/F28 -> 0
A29: C19 | C29: 500 | D29: =C29*0.66*1 -> 330 | E29: 1.12 | F29: =D29/3 -> 110 | G29: =F29/B29 -> #DIV/0! | H29: =_xlfn.XLOOKUP(A29,BC!A:A,BC!G:G,0) -> 有参转录组（RNA-seq） | I29: =_xlfn.XLOOKUP(A29,BC!A:A,BC!H:H,0) -> 广州奥智生物科技有限公司 | J29: =40-G29 -> #DIV/0! | M29: =22*L29/F29 -> 0
A30: C20 | C30: 500 | D30: =C30*0.66*1 -> 330 | E30: 11.21 | F30: =D30 -> 330 | G30: =F30/B30 -> #DIV/0! | H30: =_xlfn.XLOOKUP(A30,BC!A:A,BC!G:G,0) -> 10X-3-转录组 | I30: =_xlfn.XLOOKUP(A30,BC!A:A,BC!H:H,0) -> 广州奥智生物科技有限公司 | J30: =40-G30 -> #DIV/0! | M30: =22*L30/F30 -> 0
A31: C21 | C31: 500 | D31: =C31*0.66*1 -> 330 | E31: 22.4 | F31: =D31 -> 330 | G31: =F31/B31 -> #DIV/0! | H31: =_xlfn.XLOOKUP(A31,BC!A:A,BC!G:G,0) -> BCR文库 | I31: =_xlfn.XLOOKUP(A31,BC!A:A,BC!H:H,0) -> 江西烈冰生物科技有限公司 | J31: =40-G31 -> #DIV/0! | M31: =22*L31/F31 -> 0
A32: C22 | C32: 550 | D32: =C32*0.66*1 -> 363 | E32: 39.1 | F32: =D32 -> 363 | G32: =F32/B32 -> #DIV/0! | H32: =_xlfn.XLOOKUP(A32,BC!A:A,BC!G:G,0) -> BD-单细胞 | I32: =_xlfn.XLOOKUP(A32,BC!A:A,BC!H:H,0) -> 江西烈冰生物科技有限公司 | J32: =40-G32 -> #DIV/0! | M32: =22*L32/F32 -> 0
A33: C23 | C33: 500 | D33: =C33*0.66*1 -> 330 | E33: 17.99 | F33: =D33 -> 330 | G33: =F33/B33 -> #DIV/0! | H33: =_xlfn.XLOOKUP(A33,BC!A:A,BC!G:G,0) -> TCR文库 | I33: =_xlfn.XLOOKUP(A33,BC!A:A,BC!H:H,0) -> 江西烈冰生物科技有限公司 | J33: =40-G33 -> #DIV/0! | M33: =22*L33/F33 -> 0
A34: C24 | C34: 400 | D34: =C34*0.66*1 -> 264 | E34: 62.63 | F34: =D34 -> 264 | G34: =F34/B34 -> #DIV/0! | H34: =_xlfn.XLOOKUP(A34,BC!A:A,BC!G:G,0) -> mRNA | I34: =_xlfn.XLOOKUP(A34,BC!A:A,BC!H:H,0) -> 江西烈冰生物科技有限公司 | J34: =40-G34 -> #DIV/0! | M34: =22*L34/F34 -> 0
A35: C25 | C35: 400 | D35: =C35*0.66*1 -> 264 | E35: 94.08 | F35: =D35 -> 264 | G35: =F35/B35 -> #DIV/0! | H35: =_xlfn.XLOOKUP(A35,BC!A:A,BC!G:G,0) -> mRNA | I35: =_xlfn.XLOOKUP(A35,BC!A:A,BC!H:H,0) -> 江西烈冰生物科技有限公司 | J35: =40-G35 -> #DIV/0! | M35: =22*L35/F35 -> 0
E36: =SUM(E11:E35) -> 3634.78

Sheet T7+制备
A1: laneID | B1: 文库ssDNA编号 | C1: SSDNA浓度 | D1: 平均片段 | F1: 150fmol对应质量（ng） | G1: 投入摩尔数 | H1: 数据量（G) | I1: 理论数据量占比 | J1: 调整比例 | L1: 实际投入占比 | M1: ssDNA取样体积 | N1: 文库类型 | O1: 客户单位 | P1: TE补充体积 | Q1: 实际调整比例
A2: 260720B | B2: B1 | D2: 378 | E2: {=IF(ROUND(ABS(D2-MEDIAN(IF($A$2:$A$908=A2,$D$2:$D$908))),0)>100,IF(D2>MEDIAN(IF($A$2:$A$908=A2,$D$2:$D$908)),"偏大"&ROUND(ABS(D2-MEDIAN(IF($A$2:$A$908=A2,$D$2:$D$908))),0)&"bp","偏小"&ROUND(ABS(D2-MEDIAN(IF($A$2:$A$908=A2,$D$2:$D$908))),0)&"bp"),"正常")} -> 正常 | F2: =D2*0.33*G2*0.001 -> 17.00548 | G2: =900*L2 -> 136.3274 | H2: 570 | I2: =H2/$H$9 -> 0.15147489 | J2: 1 | K2: =I2*J2 -> 0.15147489 | L2: =K2/$K$9 -> 0.15147489 | M2: =F2/C2 -> #DIV/0! | N2: 宏基因组文库 | O2: 广东美格基因科技有限公司 | Q2: =L2/I2 -> 1
A3: 260720B | B3: B2 | D3: 371 | E3: {=IF(ROUND(ABS(D3-MEDIAN(IF($A$2:$A$908=A3,$D$2:$D$908))),0)>100,IF(D3>MEDIAN(IF($A$2:$A$908=A3,$D$2:$D$908)),"偏大"&ROUND(ABS(D3-MEDIAN(IF($A$2:$A$908=A3,$D$2:$D$908))),0)&"bp","偏小"&ROUND(ABS(D3-MEDIAN(IF($A$2:$A$908=A3,$D$2:$D$908))),0)&"bp"),"正常")} -> 正常 | F3: =D3*0.33*G3*0.001 -> 16.397746 | G3: =900*L3 -> 133.93569 | H3: 560 | I3: =H3/$H$9 -> 0.14881743 | J3: 1 | K3: =I3*J3 -> 0.14881743 | L3: =K3/$K$9 -> 0.14881743 | M3: =F3/C3 -> #DIV/0! | N3: 宏基因组文库 | O3: 广东美格基因科技有限公司 | Q3: =L3/I3 -> 1
A4: 260720B | B4: B3 | D4: 418 | E4: {=IF(ROUND(ABS(D4-MEDIAN(IF($A$2:$A$908=A4,$D$2:$D$908))),0)>100,IF(D4>MEDIAN(IF($A$2:$A$908=A4,$D$2:$D$908)),"偏大"&ROUND(ABS(D4-MEDIAN(IF($A$2:$A$908=A4,$D$2:$D$908))),0)&"bp","偏小"&ROUND(ABS(D4-MEDIAN(IF($A$2:$A$908=A4,$D$2:$D$908))),0)&"bp"),"正常")} -> 正常 | F4: =D4*0.33*G4*0.001 -> 18.805001 | G4: =900*L4 -> 136.3274 | H4: 570 | I4: =H4/$H$9 -> 0.15147489 | J4: 1 | K4: =I4*J4 -> 0.15147489 | L4: =K4/$K$9 -> 0.15147489 | M4: =F4/C4 -> #DIV/0! | N4: 宏基因组文库 | O4: 广东美格基因科技有限公司 | Q4: =L4/I4 -> 1
A5: 260720B | B5: B4 | D5: 414 | E5: {=IF(ROUND(ABS(D5-MEDIAN(IF($A$2:$A$908=A5,$D$2:$D$908))),0)>100,IF(D5>MEDIAN(IF($A$2:$A$908=A5,$D$2:$D$908)),"偏大"&ROUND(ABS(D5-MEDIAN(IF($A$2:$A$908=A5,$D$2:$D$908))),0)&"bp","偏小"&ROUND(ABS(D5-MEDIAN(IF($A$2:$A$908=A5,$D$2:$D$908))),0)&"bp"),"正常")} -> 正常 | F5: =D5*0.33*G5*0.001 -> 18.625049 | G5: =900*L5 -> 136.3274 | H5: 570 | I5: =H5/$H$9 -> 0.15147489 | J5: 1 | K5: =I5*J5 -> 0.15147489 | L5: =K5/$K$9 -> 0.15147489 | M5: =F5/C5 -> #DIV/0! | N5: 宏基因组文库 | O5: 广东美格基因科技有限公司 | Q5: =L5/I5 -> 1
A6: 260720B | B6: B5 | D6: 384 | E6: {=IF(ROUND(ABS(D6-MEDIAN(IF($A$2:$A$908=A6,$D$2:$D$908))),0)>100,IF(D6>MEDIAN(IF($A$2:$A$908=A6,$D$2:$D$908)),"偏大"&ROUND(ABS(D6-MEDIAN(IF($A$2:$A$908=A6,$D$2:$D$908))),0)&"bp","偏小"&ROUND(ABS(D6-MEDIAN(IF($A$2:$A$908=A6,$D$2:$D$908))),0)&"bp"),"正常")} -> 正常 | F6: =D6*0.33*G6*0.001 -> 17.275408 | G6: =900*L6 -> 136.3274 | H6: 570 | I6: =H6/$H$9 -> 0.15147489 | J6: 1 | K6: =I6*J6 -> 0.15147489 | L6: =K6/$K$9 -> 0.15147489 | M6: =F6/C6 -> #DIV/0! | N6: 宏基因组文库 | O6: 广东美格基因科技有限公司 | Q6: =L6/I6 -> 1
A7: 260720B | B7: B6 | D7: 408 | E7: {=IF(ROUND(ABS(D7-MEDIAN(IF($A$2:$A$908=A7,$D$2:$D$908))),0)>100,IF(D7>MEDIAN(IF($A$2:$A$908=A7,$D$2:$D$908)),"偏大"&ROUND(ABS(D7-MEDIAN(IF($A$2:$A$908=A7,$D$2:$D$908))),0)&"bp","偏小"&ROUND(ABS(D7-MEDIAN(IF($A$2:$A$908=A7,$D$2:$D$908))),0)&"bp"),"正常")} -> 正常 | F7: =D7*0.33*G7*0.001 -> 18.451727 | G7: =900*L7 -> 137.04491 | H7: 573 | I7: =H7/$H$9 -> 0.15227212 | J7: 1 | K7: =I7*J7 -> 0.15227212 | L7: =K7/$K$9 -> 0.15227212 | M7: =F7/C7 -> #DIV/0! | N7: 宏基因组文库 | O7: 广东美格基因科技有限公司 | Q7: =L7/I7 -> 1
A8: 260720B | B8: B7 | D8: 416 | E8: {=IF(ROUND(ABS(D8-MEDIAN(IF($A$2:$A$908=A8,$D$2:$D$908))),0)>100,IF(D8>MEDIAN(IF($A$2:$A$908=A8,$D$2:$D$908)),"偏大"&ROUND(ABS(D8-MEDIAN(IF($A$2:$A$908=A8,$D$2:$D$908))),0)&"bp","偏小"&ROUND(ABS(D8-MEDIAN(IF($A$2:$A$908=A8,$D$2:$D$908))),0)&"bp"),"正常")} -> 正常 | F8: =D8*0.33*G8*0.001 -> 11.491682 | G8: =900*L8 -> 83.709806 | H8: 350 | I8: =H8/$H$9 -> 0.093010896 | J8: 1 | K8: =I8*J8 -> 0.093010896 | L8: =K8/$K$9 -> 0.093010896 | M8: =F8/C8 -> #DIV/0! | N8: 宏基因组文库 | O8: 广东美格基因科技有限公司 | Q8: =L8/I8 -> 1
D9: =MEDIAN(D2:D8) -> 408 | H9: =SUM(H2:H8) -> 3763 | K9: =SUM(K2:K8) -> 1 | M9: =SUM(M2:M8) -> #DIV/0! | P9: =96-M9 -> #DIV/0!
A11: 260720C | B11: C1 | D11: 323.5 | E11: {=IF(ROUND(ABS(D11-MEDIAN(IF($A$2:$A$908=A11,$D$2:$D$908))),0)>100,IF(D11>MEDIAN(IF($A$2:$A$908=A11,$D$2:$D$908)),"偏大"&ROUND(ABS(D11-MEDIAN(IF($A$2:$A$908=A11,$D$2:$D$908))),0)&"bp","偏小"&ROUND(ABS(D11-MEDIAN(IF($A$2:$A$908=A11,$D$2:$D$908))),0)&"bp"),"正常")} -> 偏大324bp | F11: =D11*0.33*G11*0.001 -> #DIV/0! | G11: =900*L11 -> #DIV/0! | H11: 2.18 | I11: =H11/$H$36 -> 0.0005997612 | K11: =I11*J11 -> 0 | L11: =K11/$K$36 -> #DIV/0! | M11: =F11/C11 -> #DIV/0! | N11: 基因组文库 | O11: 武汉百易汇能生物科技有限公司 | Q11: =L11/I11 -> #DIV/0!
A12: 260720C | B12: C2 | D12: 335.33333 | E12: {=IF(ROUND(ABS(D12-MEDIAN(IF($A$2:$A$908=A12,$D$2:$D$908))),0)>100,IF(D12>MEDIAN(IF($A$2:$A$908=A12,$D$2:$D$908)),"偏大"&ROUND(ABS(D12-MEDIAN(IF($A$2:$A$908=A12,$D$2:$D$908))),0)&"bp","偏小"&ROUND(ABS(D12-MEDIAN(IF($A$2:$A$908=A12,$D$2:$D$908))),0)&"bp"),"正常")} -> 偏大335bp | F12: =D12*0.33*G12*0.001 -> #DIV/0! | G12: =900*L12 -> #DIV/0! | H12: 34.87 | I12: =H12/$H$36 -> 0.0095934279 | K12: =I12*J12 -> 0 | L12: =K12/$K$36 -> #DIV/0! | M12: =F12/C12 -> #DIV/0! | N12: 链特异性文库 | O12: 武汉百易汇能生物科技有限公司 | Q12: =L12/I12 -> #DIV/0!
A13: 260720C | B13: C3 | D13: 334 | E13: {=IF(ROUND(ABS(D13-MEDIAN(IF($A$2:$A$908=A13,$D$2:$D$908))),0)>100,IF(D13>MEDIAN(IF($A$2:$A$908=A13,$D$2:$D$908)),"偏大"&ROUND(ABS(D13-MEDIAN(IF($A$2:$A$908=A13,$D$2:$D$908))),0)&"bp","偏小"&ROUND(ABS(D13-MEDIAN(IF($A$2:$A$908=A13,$D$2:$D$908))),0)&"bp"),"正常")} -> 偏大334bp | F13: =D13*0.33*G13*0.001 -> #DIV/0! | G13: =900*L13 -> #DIV/0! | H13: 11.98 | I13: =H13/$H$36 -> 0.0032959354 | K13: =I13*J13 -> 0 | L13: =K13/$K$36 -> #DIV/0! | M13: =F13/C13 -> #DIV/0! | N13: 转录组文库 | O13: 武汉百易汇能生物科技有限公司 | Q13: =L13/I13 -> #DIV/0!
A14: 260720C | B14: C4 | D14: 332 | E14: {=IF(ROUND(ABS(D14-MEDIAN(IF($A$2:$A$908=A14,$D$2:$D$908))),0)>100,IF(D14>MEDIAN(IF($A$2:$A$908=A14,$D$2:$D$908)),"偏大"&ROUND(ABS(D14-MEDIAN(IF($A$2:$A$908=A14,$D$2:$D$908))),0)&"bp","偏小"&ROUND(ABS(D14-MEDIAN(IF($A$2:$A$908=A14,$D$2:$D$908))),0)&"bp"),"正常")} -> 偏大332bp | F14: =D14*0.33*G14*0.001 -> #DIV/0! | G14: =900*L14 -> #DIV/0! | H14: 12.17 | I14: =H14/$H$36 -> 0.0033482081 | K14: =I14*J14 -> 0 | L14: =K14/$K$36 -> #DIV/0! | M14: =F14/C14 -> #DIV/0! | N14: 基因组文库 | O14: 武汉百易汇能生物科技有限公司 | Q14: =L14/I14 -> #DIV/0!
A15: 260720C | B15: C5 | D15: 450 | E15: {=IF(ROUND(ABS(D15-MEDIAN(IF($A$2:$A$908=A15,$D$2:$D$908))),0)>100,IF(D15>MEDIAN(IF($A$2:$A$908=A15,$D$2:$D$908)),"偏大"&ROUND(ABS(D15-MEDIAN(IF($A$2:$A$908=A15,$D$2:$D$908))),0)&"bp","偏小"&ROUND(ABS(D15-MEDIAN(IF($A$2:$A$908=A15,$D$2:$D$908))),0)&"bp"),"正常")} -> 偏大450bp | F15: =D15*0.33*G15*0.001 -> #DIV/0! | G15: =900*L15 -> #DIV/0! | H15: 4.25 | I15: =H15/$H$36 -> 0.0011692592 | K15: =I15*J15 -> 0 | L15: =K15/$K$36 -> #DIV/0! | M15: =F15/C15 -> #DIV/0! | N15: 华大-C4-转录组 | O15: 广州基迪奥科技服务有限公司 | Q15: =L15/I15 -> #DIV/0!
A16: 260720C | B16: C6 | D16: 200 | E16: {=IF(ROUND(ABS(D16-MEDIAN(IF($A$2:$A$908=A16,$D$2:$D$908))),0)>100,IF(D16>MEDIAN(IF($A$2:$A$908=A16,$D$2:$D$908)),"偏大"&ROUND(ABS(D16-MEDIAN(IF($A$2:$A$908=A16,$D$2:$D$908))),0)&"bp","偏小"&ROUND(ABS(D16-MEDIAN(IF($A$2:$A$908=A16,$D$2:$D$908))),0)&"bp"),"正常")} -> 偏大200bp | F16: =D16*0.33*G16*0.001 -> #DIV/0! | G16: =900*L16 -> #DIV/0! | H16: 0.72 | I16: =H16/$H$36 -> 0.00019808627 | K16: =I16*J16 -> 0 | L16: =K16/$K$36 -> #DIV/0! | M16: =F16/C16 -> #DIV/0! | N16: 华大-C4-oligo | O16: 广州奥智生物科技有限公司 | Q16: =L16/I16 -> #DIV/0!
A17: 260720C | B17: C7 | E17: {=IF(ROUND(ABS(D17-MEDIAN(IF($A$2:$A$908=A17,$D$2:$D$908))),0)>100,IF(D17>MEDIAN(IF($A$2:$A$908=A17,$D$2:$D$908)),"偏大"&ROUND(ABS(D17-MEDIAN(IF($A$2:$A$908=A17,$D$2:$D$908))),0)&"bp","偏小"&ROUND(ABS(D17-MEDIAN(IF($A$2:$A$908=A17,$D$2:$D$908))),0)&"bp"),"正常")} -> 正常 | F17: =D17*0.33*G17*0.001 -> #DIV/0! | G17: =900*L17 -> #DIV/0! | H17: 4 | I17: =H17/$H$36 -> 0.0011004793 | K17: =I17*J17 -> 0 | L17: =K17/$K$36 -> #DIV/0! | M17: =F17/C17 -> #DIV/0! | N17: 真核转录组文库 | O17: 广东美格基因科技有限公司 | Q17: =L17/I17 -> #DIV/0!
A18: 260720C | B18: C8 | E18: {=IF(ROUND(ABS(D18-MEDIAN(IF($A$2:$A$908=A18,$D$2:$D$908))),0)>100,IF(D18>MEDIAN(IF($A$2:$A$908=A18,$D$2:$D$908)),"偏大"&ROUND(ABS(D18-MEDIAN(IF($A$2:$A$908=A18,$D$2:$D$908))),0)&"bp","偏小"&ROUND(ABS(D18-MEDIAN(IF($A$2:$A$908=A18,$D$2:$D$908))),0)&"bp"),"正常")} -> 正常 | F18: =D18*0.33*G18*0.001 -> #DIV/0! | G18: =900*L18 -> #DIV/0! | H18: 400 | I18: =H18/$H$36 -> 0.11004793 | K18: =I18*J18 -> 0 | L18: =K18/$K$36 -> #DIV/0! | M18: =F18/C18 -> #DIV/0! | N18: 新格元3端单细胞转录组 | O18: 深圳达普生物科技有限公司 | Q18: =L18/I18 -> #DIV/0!
A19: 260720C | B19: C9 | E19: {=IF(ROUND(ABS(D19-MEDIAN(IF($A$2:$A$908=A19,$D$2:$D$908))),0)>100,IF(D19>MEDIAN(IF($A$2:$A$908=A19,$D$2:$D$908)),"偏大"&ROUND(ABS(D19-MEDIAN(IF($A$2:$A$908=A19,$D$2:$D$908))),0)&"bp","偏小"&ROUND(ABS(D19-MEDIAN(IF($A$2:$A$908=A19,$D$2:$D$908))),0)&"bp"),"正常")} -> 正常 | F19: =D19*0.33*G19*0.001 -> #DIV/0! | G19: =900*L19 -> #DIV/0! | H19: 108 | I19: =H19/$H$36 -> 0.02971294 | K19: =I19*J19 -> 0 | L19: =K19/$K$36 -> #DIV/0! | M19: =F19/C19 -> #DIV/0! | N19: mRNA-T7 | O19: 武汉格信生物科技有限公司 | Q19: =L19/I19 -> #DIV/0!
A20: 260720C | B20: C10 | E20: {=IF(ROUND(ABS(D20-MEDIAN(IF($A$2:$A$908=A20,$D$2:$D$908))),0)>100,IF(D20>MEDIAN(IF($A$2:$A$908=A20,$D$2:$D$908)),"偏大"&ROUND(ABS(D20-MEDIAN(IF($A$2:$A$908=A20,$D$2:$D$908))),0)&"bp","偏小"&ROUND(ABS(D20-MEDIAN(IF($A$2:$A$908=A20,$D$2:$D$908))),0)&"bp"),"正常")} -> 正常 | F20: =D20*0.33*G20*0.001 -> #DIV/0! | G20: =900*L20 -> #DIV/0! | H20: 780 | I20: =H20/$H$36 -> 0.21459346 | K20: =I20*J20 -> 0 | L20: =K20/$K$36 -> #DIV/0! | M20: =F20/C20 -> #DIV/0! | N20: singleron-3'转录组文库 | O20: 南京通元医学检验实验室有限公司 | Q20: =L20/I20 -> #DIV/0!
A21: 260720C | B21: C11 | E21: {=IF(ROUND(ABS(D21-MEDIAN(IF($A$2:$A$908=A21,$D$2:$D$908))),0)>100,IF(D21>MEDIAN(IF($A$2:$A$908=A21,$D$2:$D$908)),"偏大"&ROUND(ABS(D21-MEDIAN(IF($A$2:$A$908=A21,$D$2:$D$908))),0)&"bp","偏小"&ROUND(ABS(D21-MEDIAN(IF($A$2:$A$908=A21,$D$2:$D$908))),0)&"bp"),"正常")} -> 正常 | F21: =D21*0.33*G21*0.001 -> #DIV/0! | G21: =900*L21 -> #DIV/0! | H21: 24 | I21: =H21/$H$36 -> 0.0066028756 | K21: =I21*J21 -> 0 | L21: =K21/$K$36 -> #DIV/0! | M21: =F21/C21 -> #DIV/0! | N21: singleron-单细胞TCR文库 | O21: 南京通元医学检验实验室有限公司 | Q21: =L21/I21 -> #DIV/0!
A22: 260720C | B22: C12 | E22: {=IF(ROUND(ABS(D22-MEDIAN(IF($A$2:$A$908=A22,$D$2:$D$908))),0)>100,IF(D22>MEDIAN(IF($A$2:$A$908=A22,$D$2:$D$908)),"偏大"&ROUND(ABS(D22-MEDIAN(IF($A$2:$A$908=A22,$D$2:$D$908))),0)&"bp","偏小"&ROUND(ABS(D22-MEDIAN(IF($A$2:$A$908=A22,$D$2:$D$908))),0)&"bp"),"正常")} -> 正常 | F22: =D22*0.33*G22*0.001 -> #DIV/0! | G22: =900*L22 -> #DIV/0! | H22: 600 | I22: =H22/$H$36 -> 0.16507189 | K22: =I22*J22 -> 0 | L22: =K22/$K$36 -> #DIV/0! | M22: =F22/C22 -> #DIV/0! | N22: BD-单细胞 | O22: 江西烈冰生物科技有限公司 | Q22: =L22/I22 -> #DIV/0!
A23: 260720C | B23: C13 | E23: {=IF(ROUND(ABS(D23-MEDIAN(IF($A$2:$A$908=A23,$D$2:$D$908))),0)>100,IF(D23>MEDIAN(IF($A$2:$A$908=A23,$D$2:$D$908)),"偏大"&ROUND(ABS(D23-MEDIAN(IF($A$2:$A$908=A23,$D$2:$D$908))),0)&"bp","偏小"&ROUND(ABS(D23-MEDIAN(IF($A$2:$A$908=A23,$D$2:$D$908))),0)&"bp"),"正常")} -> 正常 | F23: =D23*0.33*G23*0.001 -> #DIV/0! | G23: =900*L23 -> #DIV/0! | H23: 900 | I23: =H23/$H$36 -> 0.24760783 | K23: =I23*J23 -> 0 | L23: =K23/$K$36 -> #DIV/0! | M23: =F23/C23 -> #DIV/0! | N23: 新格元3端单细胞转录组 | O23: 深圳达普生物科技有限公司 | Q23: =L23/I23 -> #DIV/0!
A24: 260720C | B24: C14 | E24: {=IF(ROUND(ABS(D24-MEDIAN(IF($A$2:$A$908=A24,$D$2:$D$908))),0)>100,IF(D24>MEDIAN(IF($A$2:$A$908=A24,$D$2:$D$908)),"偏大"&ROUND(ABS(D24-MEDIAN(IF($A$2:$A$908=A24,$D$2:$D$908))),0)&"bp","偏小"&ROUND(ABS(D24-MEDIAN(IF($A$2:$A$908=A24,$D$2:$D$908))),0)&"bp"),"正常")} -> 正常 | F24: =D24*0.33*G24*0.001 -> #DIV/0! | G24: =900*L24 -> #DIV/0! | H24: 450 | I24: =H24/$H$36 -> 0.12380392 | K24: =I24*J24 -> 0 | L24: =K24/$K$36 -> #DIV/0! | M24: =F24/C24 -> #DIV/0! | N24: 新格元3端单细胞转录组 | O24: 深圳达普生物科技有限公司 | Q24: =L24/I24 -> #DIV/0!
A25: 260720C | B25: C15 | E25: {=IF(ROUND(ABS(D25-MEDIAN(IF($A$2:$A$908=A25,$D$2:$D$908))),0)>100,IF(D25>MEDIAN(IF($A$2:$A$908=A25,$D$2:$D$908)),"偏大"&ROUND(ABS(D25-MEDIAN(IF($A$2:$A$908=A25,$D$2:$D$908))),0)&"bp","偏小"&ROUND(ABS(D25-MEDIAN(IF($A$2:$A$908=A25,$D$2:$D$908))),0)&"bp"),"正常")} -> 正常 | F25: =D25*0.33*G25*0.001 -> #DIV/0! | G25: =900*L25 -> #DIV/0! | H25: 10 | I25: =H25/$H$36 -> 0.0027511981 | K25: =I25*J25 -> 0 | L25: =K25/$K$36 -> #DIV/0! | M25: =F25/C25 -> #DIV/0! | N25: 宏基因组文库 | O25: 广东美格基因科技有限公司 | Q25: =L25/I25 -> #DIV/0!
A26: 260720C | B26: C16 | E26: {=IF(ROUND(ABS(D26-MEDIAN(IF($A$2:$A$908=A26,$D$2:$D$908))),0)>100,IF(D26>MEDIAN(IF($A$2:$A$908=A26,$D$2:$D$908)),"偏大"&ROUND(ABS(D26-MEDIAN(IF($A$2:$A$908=A26,$D$2:$D$908))),0)&"bp","偏小"&ROUND(ABS(D26-MEDIAN(IF($A$2:$A$908=A26,$D$2:$D$908))),0)&"bp"),"正常")} -> 正常 | F26: =D26*0.33*G26*0.001 -> #DIV/0! | G26: =900*L26 -> #DIV/0! | H26: 25 | I26: =H26/$H$36 -> 0.0068779954 | K26: =I26*J26 -> 0 | L26: =K26/$K$36 -> #DIV/0! | M26: =F26/C26 -> #DIV/0! | N26: 宏基因组文库 | O26: 广东美格基因科技有限公司 | Q26: =L26/I26 -> #DIV/0!
A27: 260720C | B27: C17 | E27: {=IF(ROUND(ABS(D27-MEDIAN(IF($A$2:$A$908=A27,$D$2:$D$908))),0)>100,IF(D27>MEDIAN(IF($A$2:$A$908=A27,$D$2:$D$908)),"偏大"&ROUND(ABS(D27-MEDIAN(IF($A$2:$A$908=A27,$D$2:$D$908))),0)&"bp","偏小"&ROUND(ABS(D27-MEDIAN(IF($A$2:$A$908=A27,$D$2:$D$908))),0)&"bp"),"正常")} -> 正常 | F27: =D27*0.33*G27*0.001 -> #DIV/0! | G27: =900*L27 -> #DIV/0! | H27: 19 | I27: =H27/$H$36 -> 0.0052272765 | K27: =I27*J27 -> 0 | L27: =K27/$K$36 -> #DIV/0! | M27: =F27/C27 -> #DIV/0! | N27: 宏基因组文库 | O27: 广东美格基因科技有限公司 | Q27: =L27/I27 -> #DIV/0!
A28: 260720C | B28: C18 | E28: {=IF(ROUND(ABS(D28-MEDIAN(IF($A$2:$A$908=A28,$D$2:$D$908))),0)>100,IF(D28>MEDIAN(IF($A$2:$A$908=A28,$D$2:$D$908)),"偏大"&ROUND(ABS(D28-MEDIAN(IF($A$2:$A$908=A28,$D$2:$D$908))),0)&"bp","偏小"&ROUND(ABS(D28-MEDIAN(IF($A$2:$A$908=A28,$D$2:$D$908))),0)&"bp"),"正常")} -> 正常 | F28: =D28*0.33*G28*0.001 -> #DIV/0! | G28: =900*L28 -> #DIV/0! | H28: 0.08 | I28: =H28/$H$36 -> 2.2009585e-05 | K28: =I28*J28 -> 0 | L28: =K28/$K$36 -> #DIV/0! | M28: =F28/C28 -> #DIV/0! | N28: 有参转录组（RNA-seq） | O28: 广州奥智生物科技有限公司 | Q28: =L28/I28 -> #DIV/0!
... A35: 260720C | B35: C25 | E35: {=IF(ROUND(ABS(D35-MEDIAN(IF($A$2:$A$908=A35,$D$2:$D$908))),0)>100,IF(D35>MEDIAN(IF($A$2:$A$908=A35,$D$2:$D$908)),"偏大"&ROUND(ABS(D35-MEDIAN(IF($A$2:$A$908=A35,$D$2:$D$908))),0)&"bp","偏小"&ROUND(ABS(D35-MEDIAN(IF($A$2:$A$908=A35,$D$2:$D$908))),0)&"bp"),"正常")} -> 正常 | F35: =D35*0.33*G35*0.001 -> #DIV/0! | G35: =900*L35 -> #DIV/0! | H35: 94.08 | I35: =H35/$H$36 -> 0.025883272 | K35: =I35*J35 -> 0 | L35: =K35/$K$36 -> #DIV/0! | M35: =F35/C35 -> #DIV/0! | N35: mRNA | O35: 江西烈冰生物科技有限公司 | Q35: =L35/I35 -> #DIV/0!
D36: =MEDIAN(D11:D35) -> 333 | H36: =SUM(H11:H35) -> 3634.78 | K36: =SUM(K11:K35) -> 0 | M36: =SUM(M11:M35) -> #DIV/0! | P36: =96-M36 -> #DIV/0!

Sheet Sheet1
A1: lane编号 | B1: lane编号
A2: A1 | B2: B1 | F2: C7(30循环)
A3: A2 | B3: B2 | F3: C8(20循环)
A4: A3 | B4: B3 | F4: C9(10循环)
A5: A4 | B5: B4 | F5: C10(10循环)
A6: A5 | B6: B5 | F6: C11(10循环)
A7: A6 | B7: B6 | F7: C12(10循环)
A8: A7 | B8: B7
A9: A8 | B9: B8
A10: A9 | B10: B9
A11: A10 | B11: B10
A12: A11 | B12: B11
A13: A12 | B13: B12
B14: B13
B15: B14
B16: B15
B17: B16
B18: B17
B19: B18 | L19: HGC-POOL-26077997
B20: B19
B21: B20
F26: B1(10循环) | H26: A1(10循环)
F27: B2(10循环) | H27: A2(10循环)
F28: B3(10循环) | H28: A3(10循环)
F29: B4(10循环) | H29: A4(10循环)
F30: B5(10循环) | H30: A5(10循环)
F31: B6(10循环) | H31: A6(10循环)
F32: B7(10循环) | H32: A7(10循环)
F33: B8(10循环) | H33: A8(10循环)
F34: B9(10循环)
L43: HGC-POOL-26077998

Sheet B1-B3
A1: lane编号 | B1: 文库编号 | C1: 摩尔浓度(nM/L） | D1: 数据量（G) | E1: 文库摩尔质量（nM） | F1: 最终取样体积（ul） | G1: 混合文库摩尔质量总和 | H1: 混合文库总体积 | I1: 混合文库浓度（nM/L） | J1: 备注
A2: XB1 | B2: HGC-Lib-2460394 | C2: 15.7 | D2: 70 | E2: =D2*0.3 -> 21 | F2: =E2/C2 -> 1.3375796 | G2: =SUM(E2:E11) -> 300 | H2: =SUM(F2:F11) -> 16.990508 | I2: =G2/H2 -> 17.656918 | J2: singleron-3'全长转录组文库 | L2: =VLOOKUP(B2,'[1]7月份'!$E:$N,6,0) -> 15.7 | M2: =L2=C2 -> TRUE | T2: =VLOOKUP(B2,[2]B!$C:$K,9,0) -> HGC20221109005-0200
B3: HGC-Lib-2460819 | C3: 23.4 | D3: 120 | E3: =D3*0.3 -> 36 | F3: =E3/C3 -> 1.5384615 | J3: singleron-3'全长转录组文库 | L3: =VLOOKUP(B3,'[1]8月份'!$E:$N,6,0) -> 23.4 | M3: =L3=C3 -> TRUE | T3: =VLOOKUP(B3,[2]B!$C:$K,9,0) -> HGC20221109005-0203
B4: HGC-Lib-2460820 | C4: 24.2 | D4: 120 | E4: =D4*0.3 -> 36 | F4: =E4/C4 -> 1.4876033 | J4: singleron-3'全长转录组文库 | L4: =VLOOKUP(B4,'[1]8月份'!$E:$N,6,0) -> 24.2 | M4: =L4=C4 -> TRUE | T4: =VLOOKUP(B4,[2]B!$C:$K,9,0) -> HGC20221109005-0203
B5: HGC-Lib-2460806 | C5: 15.1 | D5: 90 | E5: =D5*0.3 -> 27 | F5: =E5/C5 -> 1.7880795 | J5: singleron-3'转录组文库 | L5: =VLOOKUP(B5,'[1]8月份'!$E:$N,6,0) -> 15.1 | M5: =L5=C5 -> TRUE | T5: =VLOOKUP(B5,[2]B!$C:$K,9,0) -> HGC20221109005-0203
B6: HGC-Lib-2460415 | C6: 22 | D6: 100 | E6: =D6*0.3 -> 30 | F6: =E6/C6 -> 1.3636364 | J6: singleron-3'转录组文库 | L6: =VLOOKUP(B6,'[1]7月份'!$E:$N,6,0) -> 22 | M6: =L6=C6 -> TRUE | T6: =VLOOKUP(B6,[2]B!$C:$K,9,0) -> HGC20221109005-0200
B7: HGC-Lib-2460416 | C7: 15.1 | D7: 100 | E7: =D7*0.3 -> 30 | F7: =E7/C7 -> 1.986755 | J7: singleron-3'转录组文库 | L7: =VLOOKUP(B7,'[1]7月份'!$E:$N,6,0) -> 15.1 | M7: =L7=C7 -> TRUE | O7: =I2 -> 17.656918 | T7: =VLOOKUP(B7,[2]B!$C:$K,9,0) -> HGC20221109005-0200
B8: HGC-Lib-2460417 | C8: 17.2 | D8: 100 | E8: =D8*0.3 -> 30 | F8: =E8/C8 -> 1.744186 | J8: singleron-3'转录组文库 | L8: =VLOOKUP(B8,'[1]7月份'!$E:$N,6,0) -> 17.2 | M8: =L8=C8 -> TRUE | T8: =VLOOKUP(B8,[2]B!$C:$K,9,0) -> HGC20221109005-0200
B9: HGC-Lib-2460418 | C9: 18 | D9: 100 | E9: =D9*0.3 -> 30 | F9: =E9/C9 -> 1.6666667 | J9: singleron-3'转录组文库 | L9: =VLOOKUP(B9,'[1]7月份'!$E:$N,6,0) -> 18 | M9: =L9=C9 -> TRUE | T9: =VLOOKUP(B9,[2]B!$C:$K,9,0) -> HGC20221109005-0200
B10: HGC-Lib-2460420 | C10: 26.4 | D10: 100 | E10: =D10*0.3 -> 30 | F10: =E10/C10 -> 1.1363636 | J10: singleron-3'转录组文库 | L10: =VLOOKUP(B10,'[1]7月份'!$E:$N,6,0) -> 26.4 | M10: =L10=C10 -> TRUE | T10: =VLOOKUP(B10,[2]B!$C:$K,9,0) -> HGC20221109005-0200
B11: HGC-Lib-2460425 | C11: 10.2 | D11: 100 | E11: =D11*0.3 -> 30 | F11: =E11/C11 -> 2.9411765 | J11: singleron-3'转录组文库 | L11: =VLOOKUP(B11,'[1]7月份'!$E:$N,6,0) -> 10.2 | M11: =L11=C11 -> TRUE | T11: =VLOOKUP(B11,[2]B!$C:$K,9,0) -> HGC20221109005-0200
T12: =VLOOKUP(B12,[2]B!$C:$K,9,0) -> #N/A
A13: XB2-970 | B13: HGC-Lib-2460397 | C13: 17.4 | D13: 120 | E13: =D13*0.2 -> 24 | F13: =E13/C13 -> 1.3793103 | G13: =SUM(E13:E20) -> 194 | H13: =SUM(F13:F20) -> 12.647053 | I13: =G13/H13 -> 15.339542 | J13: singleron-3'全长转录组文库 | L13: =VLOOKUP(B13,'[1]7月份'!$E:$N,6,0) -> 17.4 | M13: =L13=C13 -> TRUE | T13: =VLOOKUP(B13,[2]B!$C:$K,9,0) -> HGC20221109005-0200
B14: HGC-Lib-2460401 | C14: 12.6 | D14: 100 | E14: =D14*0.2 -> 20 | F14: =E14/C14 -> 1.5873016 | J14: singleron-3'全长转录组文库 | L14: =VLOOKUP(B14,'[1]7月份'!$E:$N,6,0) -> 12.6 | M14: =L14=C14 -> TRUE | T14: =VLOOKUP(B14,[2]B!$C:$K,9,0) -> HGC20221109005-0200
B15: HGC-Lib-2460426 | C15: 9.42 | D15: 100 | E15: =D15*0.2 -> 20 | F15: =E15/C15 -> 2.1231423 | J15: singleron-3'转录组文库 | L15: =VLOOKUP(B15,'[1]7月份'!$E:$N,6,0) -> 9.42 | M15: =L15=C15 -> TRUE | T15: =VLOOKUP(B15,[2]B!$C:$K,9,0) -> HGC20221109005-0200
B16: HGC-Lib-2460427 | C16: 10.3 | D16: 100 | E16: =D16*0.2 -> 20 | F16: =E16/C16 -> 1.9417476 | J16: singleron-3'转录组文库 | L16: =VLOOKUP(B16,'[1]7月份'!$E:$N,6,0) -> 10.3 | M16: =L16=C16 -> TRUE | T16: =VLOOKUP(B16,[2]B!$C:$K,9,0) -> HGC20221109005-0200
B17: HGC-Lib-2460428 | C17: 16 | D17: 100 | E17: =D17*0.2 -> 20 | F17: =E17/C17 -> 1.25 | J17: singleron-3'转录组文库 | L17: =VLOOKUP(B17,'[1]7月份'!$E:$N,6,0) -> 16 | M17: =L17=C17 -> TRUE | O17: =I13 -> 15.339542 | T17: =VLOOKUP(B17,[2]B!$C:$K,9,0) -> HGC20221109005-0200
B18: HGC-Lib-2460433 | C18: 22 | D18: 100 | E18: =D18*0.2 -> 20 | F18: =E18/C18 -> 0.90909091 | J18: singleron-3'转录组文库 | L18: =VLOOKUP(B18,'[1]7月份'!$E:$N,6,0) -> 22 | M18: =L18=C18 -> TRUE | T18: =VLOOKUP(B18,[2]B!$C:$K,9,0) -> HGC20221109005-0200
B19: HGC-Lib-2460804 | C19: 18.9 | D19: 150 | E19: =D19*0.2 -> 30 | F19: =E19/C19 -> 1.5873016 | J19: singleron-3'转录组文库 | L19: =VLOOKUP(B19,'[1]8月份'!$E:$N,6,0) -> 18.9 | M19: =L19=C19 -> TRUE | T19: =VLOOKUP(B19,[2]B!$C:$K,9,0) -> HGC20221109005-0203
B20: HGC-Lib-2460815 | C20: 21.4 | D20: 200 | E20: =D20*0.2 -> 40 | F20: =E20/C20 -> 1.8691589 | J20: singleron-3'转录组文库 | L20: =VLOOKUP(B20,'[1]8月份'!$E:$N,6,0) -> 21.4 | M20: =L20=C20 -> TRUE | T20: =VLOOKUP(B20,[2]B!$C:$K,9,0) -> HGC20221109005-0203
T21: =VLOOKUP(B21,[2]B!$C:$K,9,0) -> #N/A
A22: XB2-30 | B22: HGC-Lib-2460421 | C22: 18.3 | D22: 10 | E22: =D22*2.5 -> 25 | F22: =E22/C22 -> 1.3661202 | G22: =SUM(E22:E24) -> 75 | H22: =SUM(F22:F24) -> 6.2334352 | I22: =G22/H22 -> 12.031889 | J22: singleron-3'转录组文库 | L22: =VLOOKUP(B22,'[1]7月份'!$E:$N,6,0) -> 18.3 | M22: =L22=C22 -> TRUE | O22: =H22/2 -> 3.1167176 | T22: =VLOOKUP(B22,[2]B!$C:$K,9,0) -> HGC20221109005-0200
B23: HGC-Lib-2460422 | C23: 11.1 | D23: 10 | E23: =D23*2.5 -> 25 | F23: =E23/C23 -> 2.2522523 | J23: singleron-3'转录组文库 | L23: =VLOOKUP(B23,'[1]7月份'!$E:$N,6,0) -> 11.1 | M23: =L23=C23 -> TRUE | O23: =I22*2/3 -> 8.0212592 | T23: =VLOOKUP(B23,[2]B!$C:$K,9,0) -> HGC20221109005-0200
B24: HGC-Lib-2460435 | C24: 9.56 | D24: 10 | E24: =D24*2.5 -> 25 | F24: =E24/C24 -> 2.6150628 | J24: singleron-3'转录组文库 | L24: =VLOOKUP(B24,'[1]7月份'!$E:$N,6,0) -> 9.56 | M24: =L24=C24 -> TRUE | T24: =VLOOKUP(B24,[2]B!$C:$K,9,0) -> HGC20221109005-0200
T25: =VLOOKUP(B25,[2]B!$C:$K,9,0) -> #N/A
A26: XB3 | B26: HGC-Lib-2460805 | C26: 13.1 | D26: 150 | E26: =D26*0.3 -> 45 | F26: =E26/C26 -> 3.4351145 | G26: =SUM(E26:E37) -> 300.9 | H26: =SUM(F26:F37) -> 18.560359 | I26: =G26/H26 -> 16.211971 | J26: singleron-3'转录组文库 | L26: =VLOOKUP(B26,'[1]8月份'!$E:$N,6,0) -> 13.1 | M26: =L26=C26 -> TRUE | T26: =VLOOKUP(B26,[2]B!$C:$K,9,0) -> HGC20221109005-0203
B27: HGC-Lib-2460807 | C27: 19.9 | D27: 90 | E27: =D27*0.3 -> 27 | F27: =E27/C27 -> 1.3567839 | J27: singleron-3'转录组文库 | L27: =VLOOKUP(B27,'[1]8月份'!$E:$N,6,0) -> 19.9 | M27: =L27=C27 -> TRUE | T27: =VLOOKUP(B27,[2]B!$C:$K,9,0) -> HGC20221109005-0203
B28: HGC-Lib-2460808 | C28: 14.8 | D28: 100 | E28: =D28*0.3 -> 30 | F28: =E28/C28 -> 2.027027 | J28: singleron-3'转录组文库 | L28: =VLOOKUP(B28,'[1]8月份'!$E:$N,6,0) -> 14.8 | M28: =L28=C28 -> TRUE | T28: =VLOOKUP(B28,[2]B!$C:$K,9,0) -> HGC20221109005-0203
B29: HGC-Lib-2460809 | C29: 17.1 | D29: 150 | E29: =D29*0.3 -> 45 | F29: =E29/C29 -> 2.6315789 | J29: singleron-3'转录组文库 | L29: =VLOOKUP(B29,'[1]8月份'!$E:$N,6,0) -> 17.1 | M29: =L29=C29 -> TRUE | T29: =VLOOKUP(B29,[2]B!$C:$K,9,0) -> HGC20221109005-0203
B30: HGC-Lib-2460814 | C30: 15 | D30: 90 | E30: =D30*0.3 -> 27 | F30: =E30/C30 -> 1.8 | J30: singleron-3'转录组文库 | L30: =VLOOKUP(B30,'[1]8月份'!$E:$N,6,0) -> 15 | M30: =L30=C30 -> TRUE | T30: =VLOOKUP(B30,[2]B!$C:$K,9,0) -> HGC20221109005-0203
B31: HGC-Lib-2460937 | C31: 14 | D31: 30 | E31: =D31*0.3 -> 9 | F31: =E31/C31 -> 0.64285714 | J31: singleron-3'转录组文库 | L31: =VLOOKUP(B31,'[1]8月份'!$E:$N,6,0) -> 14 | M31: =L31=C31 -> TRUE | T31: =VLOOKUP(B31,[2]B!$C:$K,9,0) -> HGC20221109005-0204
B32: HGC-Lib-2460938 | C32: 18.5 | D32: 30 | E32: =D32*0.3 -> 9 | F32: =E32/C32 -> 0.48648649 | J32: singleron-3'转录组文库 | L32: =VLOOKUP(B32,'[1]8月份'!$E:$N,6,0) -> 18.5 | M32: =L32=C32 -> TRUE | O32: =I26 -> 16.211971 | T32: =VLOOKUP(B32,[2]B!$C:$K,9,0) -> HGC20221109005-0204
B33: HGC-Lib-2460974 | C33: 15.2 | D33: 13 | E33: =D33*0.3 -> 3.9 | F33: =E33/C33 -> 0.25657895 | J33: singleron-3'转录组文库 | L33: =VLOOKUP(B33,'[1]8月份'!$E:$N,6,0) -> 15.2 | M33: =L33=C33 -> TRUE | T33: =VLOOKUP(B33,[2]B!$C:$K,9,0) -> HGC20221109005-0204
B34: HGC-Lib-2460910 | C34: 16.9 | D34: 90 | E34: =D34*0.3 -> 27 | F34: =E34/C34 -> 1.5976331 | J34: singleron-3'转录组文库 | L34: =VLOOKUP(B34,'[1]8月份'!$E:$N,6,0) -> 16.9 | M34: =L34=C34 -> TRUE | T34: =VLOOKUP(B34,[2]B!$C:$K,9,0) -> HGC20221109005-0204
B35: HGC-Lib-2460911 | C35: 14.3 | D35: 90 | E35: =D35*0.3 -> 27 | F35: =E35/C35 -> 1.8881119 | J35: singleron-3'转录组文库 | L35: =VLOOKUP(B35,'[1]8月份'!$E:$N,6,0) -> 14.3 | M35: =L35=C35 -> TRUE | T35: =VLOOKUP(B35,[2]B!$C:$K,9,0) -> HGC20221109005-0204
B36: HGC-Lib-2460945 | C36: 20.8 | D36: 70 | E36: =D36*0.3 -> 21 | F36: =E36/C36 -> 1.0096154 | J36: singleron-3'全长转录组文库 | L36: =VLOOKUP(B36,'[1]8月份'!$E:$N,6,0) -> 20.8 | M36: =L36=C36 -> TRUE | T36: =VLOOKUP(B36,[2]B!$C:$K,9,0) -> HGC20221109005-0204
B37: HGC-Lib-2460921 | C37: 21 | D37: 100 | E37: =D37*0.3 -> 30 | F37: =E37/C37 -> 1.4285714 | J37: singleron-3'转录组文库 | L37: =VLOOKUP(B37,'[1]8月份'!$E:$N,6,0) -> 21 | M37: =L37=C37 -> TRUE | T37: =VLOOKUP(B37,[2]B!$C:$K,9,0) -> HGC20221109005-0204
